Workbook

Sheet README
A1: Project 1 — UAE Last-Mile Delivery Performance (Simulated Data)
A2: Excel partner-switch scenario model
A4: Data note | B4: The operational shipment dataset is simulated and was created for portfolio purposes. It is not company data and is not affiliated with Aramex. Delivery-partner names are fictional.
A5: Business question | B5: Which routes and delivery partners cause late deliveries, and what would it cost to fix them by moving volume to a different partner?
A6: Source of numbers | B6: Partner_Data holds aggregated results from the current SQL clean view (8,920 raw rows; 118 exact duplicates removed; 8,802 clean rows). Every other number in this workbook is formula-driven from Partner_Data and Inputs.
A7: How to use | B7: 1) Change the blue cells on Inputs (route, current partner, alternative partner, % moved, cost adjustment, threshold). 2) Read Model. 3) Scenarios contains a live 0–100% sensitivity and ±10% cost sensitivity. 4) Route_Screener compares partner switches by emirate. 5) Decision updates automatically. For interviews, use the 0–100% scenario table and Goal Seek instructions documented in this workbook.
A8: On-time definition | B8: On-time delivery % = on-time delivered ÷ delivered shipments with a valid delivery date. Returned/lost shipments and records without a valid delivery date are excluded from the denominator.
A9: Cost definition | B9: Time period: 2025 (12 months). Annual cost changes refer to the full 2025 analysis period; monthly cost change divides by 12.
A10: Model logic | B10: Important: this is a scenario model, not causal evidence. It assumes the alternative partner maintains its observed route-level on-time rate and cost when it receives additional volume.
A11: Key assumption | B11: Maximum acceptable cost per extra on-time delivery (Inputs) stands in for the cost of a late delivery (customer contact, re-attempt, goodwill credit). It is an assumption, not a measured figure. Replace it with a real number if available.
A12: Goal Seek check | B12: Model shows the % moved needed to reach the target by formula. To demonstrate Goal Seek: Data → What-If Analysis → Goal Seek; Set cell = Model route on-time after switch; To value = 0.9; By changing = Inputs % moved.
A13: Data Table option | B13: Scenarios uses formulas so it recalculates everywhere. To show an Excel What-If Data Table as well: list 0%–100% in a column, put =Model route on-time after switch in the cell above-right, select the range, Data → What-If Analysis → Data Table, Column input cell = Inputs % moved.
A14: Limitations | B14: Rates come from observed simulated data, so results show association, not causation. The alternative partner is assumed to keep its current on-time rate and price when it takes on extra volume. Small samples (below the Inputs threshold) are flagged.
A15: Colour legend | B15: Blue text = input you can change · Yellow fill = key assumption · Green text = link from another sheet · Black = formula · Green fill = key output.

Sheet Inputs
A1: Inputs — change the blue cells
A2: All results update automatically.
A4: Input | B4: Value | C4: Notes
A5: Route (destination emirate) | B5: Ras Al Khaimah | C5: Choose one emirate or 'All emirates'.
A6: Current delivery partner | B6: C03 | C6: Partner whose volume is moved.
A7: Alternative delivery partner | B7: C02 | C7: Partner that takes the volume. Use Route_Screener to pick it.
A8: % of current partner's route volume moved | B8: 1 | C8: 0% to 100%.
A9: Alternative partner cost adjustment | B9: 0 | C9: Price change the alternative partner may charge for extra volume (e.g. +10%). Tested at ±10% on Scenarios.
A10: Target on-time % | B10: 0.9 | C10: Operational target from the blueprint.
A11: Max acceptable cost per extra on-time delivery (AED) | B11: 40 | C11: ASSUMPTION: proxy for the cost of one late delivery (customer contact, re-attempt, goodwill credit). Replace with a real figure if available.
A12: Months in data | B12: 12 | C12: Dataset covers Jan–Dec 2025.
A13: Minimum delivered shipments for a reliable rate | B13: 50 | C13: Rates based on fewer delivered shipments are flagged as small samples.
A16: Selected partners
A17: Current partner name | B17: =IFERROR(INDEX(Lists!$C$4:$C$8,MATCH(Inputs!$B$6,Lists!$B$4:$B$8,0)),"") -> CityHop Riders
A18: Alternative partner name | B18: =IFERROR(INDEX(Lists!$C$4:$C$8,MATCH(Inputs!$B$7,Lists!$B$4:$B$8,0)),"") -> DesertLink Express
A19: Check | B19: =IF(Inputs!$B$6=Inputs!$B$7,"Choose two different partners","OK") -> OK
A21: Legend: blue = input · yellow = key assumption · black = formula · green text = link from another sheet

Sheet Model
A1: Model — partner-switch calculation
A2: All cells are formulas. Change inputs on the Inputs sheet.
A4: Scenario inputs (linked)
A5: Route | B5: =Inputs!$B$5 -> Ras Al Khaimah
A6: Current partner | B6: =Inputs!$B$6 -> C03
A7: Alternative partner | B7: =Inputs!$B$7 -> C02
A8: % moved | B8: =Inputs!$B$8 -> 1
A9: Alternative cost adjustment | B9: =Inputs!$B$9 -> 0
A11: Current partner on this route
A12: Shipments | B12: =SUMIFS(Partner_Data!$D:$D,Partner_Data!$A:$A,$B$6,Partner_Data!$C:$C,$B$5) -> 147
A13: Delivered (valid date) | B13: =SUMIFS(Partner_Data!$E:$E,Partner_Data!$A:$A,$B$6,Partner_Data!$C:$C,$B$5) -> 140
A14: On-time delivered | B14: =SUMIFS(Partner_Data!$F:$F,Partner_Data!$A:$A,$B$6,Partner_Data!$C:$C,$B$5) -> 97
A15: On-time % | B15: =IFERROR($B$14/$B$13,0) -> 0.69285714
A16: Cost per shipment (AED) | B16: =IFERROR(SUMIFS(Partner_Data!$L:$L,Partner_Data!$A:$A,$B$6,Partner_Data!$C:$C,$B$5)/SUMIFS(Partner_Data!$K:$K,Partner_Data!$A:$A,$B$6,Partner_Data!$C:$C,$B$5),0) -> 24.226259
A18: Alternative partner on this route
A19: Shipments | B19: =SUMIFS(Partner_Data!$D:$D,Partner_Data!$A:$A,$B$7,Partner_Data!$C:$C,$B$5) -> 126
A20: Delivered (valid date) | B20: =SUMIFS(Partner_Data!$E:$E,Partner_Data!$A:$A,$B$7,Partner_Data!$C:$C,$B$5) -> 123
A21: On-time delivered | B21: =SUMIFS(Partner_Data!$F:$F,Partner_Data!$A:$A,$B$7,Partner_Data!$C:$C,$B$5) -> 108
A22: On-time % | B22: =IFERROR($B$21/$B$20,0) -> 0.87804878
A23: Cost per shipment before adjustment (AED) | B23: =IFERROR(SUMIFS(Partner_Data!$L:$L,Partner_Data!$A:$A,$B$7,Partner_Data!$C:$C,$B$5)/SUMIFS(Partner_Data!$K:$K,Partner_Data!$A:$A,$B$7,Partner_Data!$C:$C,$B$5),0) -> 29.190161
A24: Cost per shipment after adjustment (AED) | B24: =$B$23*(1+$B$9) -> 29.190161
A25: Sample check | B25: =IF(OR($B$20<Inputs!$B$13,$B$13<Inputs!$B$13),"Small sample: treat with caution","OK") -> OK | C25: Flags rates based on fewer delivered shipments than the Inputs minimum.
A27: Route and company baseline
A28: Route delivered (all partners) | B28: =SUMIFS(Partner_Data!$E:$E,Partner_Data!$C:$C,$B$5) -> 500
A29: Route on-time delivered | B29: =SUMIFS(Partner_Data!$F:$F,Partner_Data!$C:$C,$B$5) -> 410
A30: Route on-time % | B30: =IFERROR($B$29/$B$28,0) -> 0.82
A31: Company delivered (all routes) | B31: =SUMIFS(Partner_Data!$E:$E,Partner_Data!$C:$C,"All emirates") -> 8488
A32: Company on-time delivered | B32: =SUMIFS(Partner_Data!$F:$F,Partner_Data!$C:$C,"All emirates") -> 7248
A33: Company on-time % | B33: =IFERROR($B$32/$B$31,0) -> 0.8539114
A35: Scenario results (full year 2025)
A36: Shipments moved | B36: =$B$12*$B$8 -> 147
A37: Delivered shipments moved | B37: =$B$13*$B$8 -> 140
A38: On-time gap: alternative − current | B38: =$B$22-$B$15 -> 0.18519164
A39: Extra on-time deliveries per year | B39: =$B$37*$B$38 -> 25.926829
A40: Route on-time % after switch | B40: =IFERROR(($B$29+$B$39)/$B$28,0) -> 0.87185366
A41: Route change (percentage points) | B41: =($B$40-$B$30)*100 -> 5.1853659
A42: Company on-time % after switch | B42: =IFERROR(($B$32+$B$39)/$B$31,0) -> 0.85696593
A43: Company change (percentage points) | B43: =($B$42-$B$33)*100 -> 0.30545275
A44: Cost change per moved shipment (AED) | B44: =$B$24-$B$16 -> 4.9639028
A45: Annual cost change (AED) | B45: =$B$36*$B$44 -> 729.69371
...

Sheet Scenarios
A1: Scenarios — live formula-driven sensitivity (0–100% moved)
A3: ="Route: "&Model!$B$5&" · "&Model!$B$6&" → "&Model!$B$7 -> Route: Ras Al Khaimah · C03 → C02
A5: % moved | B5: Route on-time % | C5: Company on-time % | D5: Extra on-time / yr | E5: Annual cost change (AED) | F5: Monthly cost change (AED) | G5: Cost per extra on-time (AED)
A6: 0 | B6: =IFERROR((Model!$B$29+Model!$B$13*A6*Model!$B$38)/Model!$B$28,0) -> 0.82 | C6: =IFERROR((Model!$B$32+Model!$B$13*A6*Model!$B$38)/Model!$B$31,0) -> 0.8539114 | D6: =Model!$B$13*A6*Model!$B$38 -> 0 | E6: =Model!$B$12*A6*Model!$B$44 -> 0 | F6: =Model!$B$12*A6*Model!$B$44/Inputs!$B$12 -> 0 | G6: =IF(D6>0,E6/D6,"n/a") -> n/a
A7: 0.1 | B7: =IFERROR((Model!$B$29+Model!$B$13*A7*Model!$B$38)/Model!$B$28,0) -> 0.82518537 | C7: =IFERROR((Model!$B$32+Model!$B$13*A7*Model!$B$38)/Model!$B$31,0) -> 0.85421686 | D7: =Model!$B$13*A7*Model!$B$38 -> 2.5926829 | E7: =Model!$B$12*A7*Model!$B$44 -> 72.969371 | F7: =Model!$B$12*A7*Model!$B$44/Inputs!$B$12 -> 6.0807809 | G7: =IF(D7>0,E7/D7,"n/a") -> 28.144348
A8: 0.2 | B8: =IFERROR((Model!$B$29+Model!$B$13*A8*Model!$B$38)/Model!$B$28,0) -> 0.83037073 | C8: =IFERROR((Model!$B$32+Model!$B$13*A8*Model!$B$38)/Model!$B$31,0) -> 0.85452231 | D8: =Model!$B$13*A8*Model!$B$38 -> 5.1853659 | E8: =Model!$B$12*A8*Model!$B$44 -> 145.93874 | F8: =Model!$B$12*A8*Model!$B$44/Inputs!$B$12 -> 12.161562 | G8: =IF(D8>0,E8/D8,"n/a") -> 28.144348
A9: 0.3 | B9: =IFERROR((Model!$B$29+Model!$B$13*A9*Model!$B$38)/Model!$B$28,0) -> 0.8355561 | C9: =IFERROR((Model!$B$32+Model!$B$13*A9*Model!$B$38)/Model!$B$31,0) -> 0.85482776 | D9: =Model!$B$13*A9*Model!$B$38 -> 7.7780488 | E9: =Model!$B$12*A9*Model!$B$44 -> 218.90811 | F9: =Model!$B$12*A9*Model!$B$44/Inputs!$B$12 -> 18.242343 | G9: =IF(D9>0,E9/D9,"n/a") -> 28.144348
A10: 0.4 | B10: =IFERROR((Model!$B$29+Model!$B$13*A10*Model!$B$38)/Model!$B$28,0) -> 0.84074146 | C10: =IFERROR((Model!$B$32+Model!$B$13*A10*Model!$B$38)/Model!$B$31,0) -> 0.85513322 | D10: =Model!$B$13*A10*Model!$B$38 -> 10.370732 | E10: =Model!$B$12*A10*Model!$B$44 -> 291.87748 | F10: =Model!$B$12*A10*Model!$B$44/Inputs!$B$12 -> 24.323124 | G10: =IF(D10>0,E10/D10,"n/a") -> 28.144348
A11: 0.5 | B11: =IFERROR((Model!$B$29+Model!$B$13*A11*Model!$B$38)/Model!$B$28,0) -> 0.84592683 | C11: =IFERROR((Model!$B$32+Model!$B$13*A11*Model!$B$38)/Model!$B$31,0) -> 0.85543867 | D11: =Model!$B$13*A11*Model!$B$38 -> 12.963415 | E11: =Model!$B$12*A11*Model!$B$44 -> 364.84685 | F11: =Model!$B$12*A11*Model!$B$44/Inputs!$B$12 -> 30.403905 | G11: =IF(D11>0,E11/D11,"n/a") -> 28.144348
A12: 0.6 | B12: =IFERROR((Model!$B$29+Model!$B$13*A12*Model!$B$38)/Model!$B$28,0) -> 0.8511122 | C12: =IFERROR((Model!$B$32+Model!$B$13*A12*Model!$B$38)/Model!$B$31,0) -> 0.85574412 | D12: =Model!$B$13*A12*Model!$B$38 -> 15.556098 | E12: =Model!$B$12*A12*Model!$B$44 -> 437.81623 | F12: =Model!$B$12*A12*Model!$B$44/Inputs!$B$12 -> 36.484685 | G12: =IF(D12>0,E12/D12,"n/a") -> 28.144348
A13: 0.7 | B13: =IFERROR((Model!$B$29+Model!$B$13*A13*Model!$B$38)/Model!$B$28,0) -> 0.85629756 | C13: =IFERROR((Model!$B$32+Model!$B$13*A13*Model!$B$38)/Model!$B$31,0) -> 0.85604957 | D13: =Model!$B$13*A13*Model!$B$38 -> 18.14878 | E13: =Model!$B$12*A13*Model!$B$44 -> 510.7856 | F13: =Model!$B$12*A13*Model!$B$44/Inputs!$B$12 -> 42.565466 | G13: =IF(D13>0,E13/D13,"n/a") -> 28.144348
A14: 0.8 | B14: =IFERROR((Model!$B$29+Model!$B$13*A14*Model!$B$38)/Model!$B$28,0) -> 0.86148293 | C14: =IFERROR((Model!$B$32+Model!$B$13*A14*Model!$B$38)/Model!$B$31,0) -> 0.85635503 | D14: =Model!$B$13*A14*Model!$B$38 -> 20.741463 | E14: =Model!$B$12*A14*Model!$B$44 -> 583.75497 | F14: =Model!$B$12*A14*Model!$B$44/Inputs!$B$12 -> 48.646247 | G14: =IF(D14>0,E14/D14,"n/a") -> 28.144348
A15: 0.9 | B15: =IFERROR((Model!$B$29+Model!$B$13*A15*Model!$B$38)/Model!$B$28,0) -> 0.86666829 | C15: =IFERROR((Model!$B$32+Model!$B$13*A15*Model!$B$38)/Model!$B$31,0) -> 0.85666048 | D15: =Model!$B$13*A15*Model!$B$38 -> 23.334146 | E15: =Model!$B$12*A15*Model!$B$44 -> 656.72434 | F15: =Model!$B$12*A15*Model!$B$44/Inputs!$B$12 -> 54.727028 | G15: =IF(D15>0,E15/D15,"n/a") -> 28.144348
A16: 1 | B16: =IFERROR((Model!$B$29+Model!$B$13*A16*Model!$B$38)/Model!$B$28,0) -> 0.87185366 | C16: =IFERROR((Model!$B$32+Model!$B$13*A16*Model!$B$38)/Model!$B$31,0) -> 0.85696593 | D16: =Model!$B$13*A16*Model!$B$38 -> 25.926829 | E16: =Model!$B$12*A16*Model!$B$44 -> 729.69371 | F16: =Model!$B$12*A16*Model!$B$44/Inputs!$B$12 -> 60.807809 | G16: =IF(D16>0,E16/D16,"n/a") -> 28.144348
A18: Target on-time % | B18: =Inputs!$B$10 -> 0.9
A19: % moved needed / target check | B19: =Model!$B$53 -> Not achievable with this switch alone
A21: Sensitivity: alternative partner cost ±10% (at the selected % moved)
A22: Cost adjustment | B22: Alt cost / shipment (AED) | C22: Annual cost change (AED) | D22: Monthly cost change (AED) | E22: Cost per extra on-time (AED) | F22: Decision | G22: Holds vs base?
A23: -0.1 | B23: =Model!$B$23*(1+A23) -> 26.271145 | C23: =Model!$B$36*(B23-Model!$B$16) -> 300.59834 | D23: =C23/Inputs!$B$12 -> 25.049862 | E23: =IF(Model!$B$39>0,C23/Model!$B$39,"n/a") -> 11.594103 | F23: =IF(Model!$B$39<=0,"Do not switch",IF(C23<=0,"Proceed",IF(E23<=Inputs!$B$11,"Proceed","Do not proceed"))) -> Proceed | G23: =IF(F23=$F$24,"Yes","No") -> Yes
A24: 0 | B24: =Model!$B$23*(1+A24) -> 29.190161 | C24: =Model!$B$36*(B24-Model!$B$16) -> 729.69371 | D24: =C24/Inputs!$B$12 -> 60.807809 | E24: =IF(Model!$B$39>0,C24/Model!$B$39,"n/a") -> 28.144348 | F24: =IF(Model!$B$39<=0,"Do not switch",IF(C24<=0,"Proceed",IF(E24<=Inputs!$B$11,"Proceed","Do not proceed"))) -> Proceed | G24: =IF(F24=$F$24,"Yes","No") -> Yes
A25: 0.1 | B25: =Model!$B$23*(1+A25) -> 32.109177 | C25: =Model!$B$36*(B25-Model!$B$16) -> 1158.7891 | D25: =C25/Inputs!$B$12 -> 96.565757 | E25: =IF(Model!$B$39>0,C25/Model!$B$39,"n/a") -> 44.694593 | F25: =IF(Model!$B$39<=0,"Do not switch",IF(C25<=0,"Proceed",IF(E25<=Inputs!$B$11,"Proceed","Do not proceed"))) -> Do not proceed | G25: =IF(F25=$F$24,"Yes","No") -> No
A27: Conclusion | B27: =IF(COUNTIF(G23:G25,"Yes")=3,"The recommendation holds when the alternative partner's price changes by ±10%.","The recommendation changes within ±10% of the alternative partner's price: treat it as marginal.") -> The recommendation changes within ±10% of the alternative partner's price: treat it as marginal.
A29: Model note | B29: Rows 6–16 are live formulas covering 0%–100% volume moved. They are intentionally transparent and recalculate when Inputs change. For an interview demonstration, use Excel What-If Data Table/Goal Seek with the same input/output cells documented in README.
A31: Interview check | B31: Base case is set to 100% moved. Goal Seek should be used only as a target-check exercise; the model also shows the maximum achievable on-time rate.

Sheet Route_Screener
A1: Route_Screener — every possible switch for the current partner
A2: Cost per extra on-time delivery (AED) if the current partner's route volume moves to each alternative. Lower is better; negative = saves money. Uses the cost adjustment on Inputs.
A4: ="Current partner: "&Inputs!$B$6&" ("&Inputs!$B$17&")" -> Current partner: C03 (CityHop Riders)
A6: Route | B6: Current on-time % | C6: C01 | D6: C02 | E6: C03 | F6: C04 | G6: C05
A7: Abu Dhabi | B7: =IFERROR(SUMIFS(Partner_Data!$F:$F,Partner_Data!$A:$A,Inputs!$B$6,Partner_Data!$C:$C,$A7)/SUMIFS(Partner_Data!$E:$E,Partner_Data!$A:$A,Inputs!$B$6,Partner_Data!$C:$C,$A7),0) -> 0.79411765 | C7: =IF(Inputs!$B$6="C01","—",IF(IFERROR(SUMIFS(Partner_Data!$F:$F,Partner_Data!$A:$A,"C01",Partner_Data!$C:$C,$A7)/SUMIFS(Partner_Data!$E:$E,Partner_Data!$A:$A,"C01",Partner_Data!$C:$C,$A7),0)-$B7<=0,"No gain",IFERROR((IFERROR(SUMIFS(Partner_Data!$L:$L,Partner_Data!$A:$A,"C01",Partner_Data!$C:$C,$A7)/SUMIFS(Partner_Data!$K:$K,Partner_Data!$A:$A,"C01",Partner_Data!$C:$C,$A7),0)*(1+Inputs!$B$9)-IFERROR(SUMIFS(Partner_Data!$L:$L,Partner_Data!$A:$A,Inputs!$B$6,Partner_Data!$C:$C,$A7)/SUMIFS(Partner_Data!$K:$K,Partner_Data!$A:$A,Inputs!$B$6,Partner_Data!$C:$C,$A7),0))*SUMIFS(Partner_Data!$D:$D,Partner_Data!$A:$A,Inputs!$B$6,Partner_Data!$C:$C,$A7)/(SUMIFS(Partner_Data!$E:$E,Partner_Data!$A:$A,Inputs!$B$6,Partner_Data!$C:$C,$A7)*(IFERROR(SUMIFS(Partner_Data!$F:$F,Partner_Data!$A:$A,"C01",Partner_Data!$C:$C,$A7)/SUMIFS(Partner_Data!$E:$E,Partner_Data!$A:$A,"C01",Partner_Data!$C:$C,$A7),0)-$B7)),"n/a"))) -> 106.49588 | D7: =IF(Inputs!$B$6="C02","—",IF(IFERROR(SUMIFS(Partner_Data!$F:$F,Partner_Data!$A:$A,"C02",Partner_Data!$C:$C,$A7)/SUMIFS(Partner_Data!$E:$E,Partner_Data!$A:$A,"C02",Partner_Data!$C:$C,$A7),0)-$B7<=0,"No gain",IFERROR((IFERROR(SUMIFS(Partner_Data!$L:$L,Partner_Data!$A:$A,"C02",Partner_Data!$C:$C,$A7)/SUMIFS(Partner_Data!$K:$K,Partner_Data!$A:$A,"C02",Partner_Data!$C:$C,$A7),0)*(1+Inputs!$B$9)-IFERROR(SUMIFS(Partner_Data!$L:$L,Partner_Data!$A:$A,Inputs!$B$6,Partner_Data!$C:$C,$A7)/SUMIFS(Partner_Data!$K:$K,Partner_Data!$A:$A,Inputs!$B$6,Partner_Data!$C:$C,$A7),0))*SUMIFS(Partner_Data!$D:$D,Partner_Data!$A:$A,Inputs!$B$6,Partner_Data!$C:$C,$A7)/(SUMIFS(Partner_Data!$E:$E,Partner_Data!$A:$A,Inputs!$B$6,Partner_Data!$C:$C,$A7)*(IFERROR(SUMIFS(Partner_Data!$F:$F,Partner_Data!$A:$A,"C02",Partner_Data!$C:$C,$A7)/SUMIFS(Partner_Data!$E:$E,Partner_Data!$A:$A,"C02",Partner_Data!$C:$C,$A7),0)-$B7)),"n/a"))) -> 75.010689 | E7: =IF(Inputs!$B$6="C03","—",IF(IFERROR(SUMIFS(Partner_Data!$F:$F,Partner_Data!$A:$A,"C03",Partner_Data!$C:$C,$A7)/SUMIFS(Partner_Data!$E:$E,Partner_Data!$A:$A,"C03",Partner_Data!$C:$C,$A7),0)-$B7<=0,"No gain",IFERROR((IFERROR(SUMIFS(Partner_Data!$L:$L,Partner_Data!$A:$A,"C03",Partner_Data!$C:$C,$A7)/SUMIFS(Partner_Data!$K:$K,Partner_Data!$A:$A,"C03",Partner_Data!$C:$C,$A7),0)*(1+Inputs!$B$9)-IFERROR(SUMIFS(Partner_Data!$L:$L,Partner_Data!$A:$A,Inputs!$B$6,Partner_Data!$C:$C,$A7)/SUMIFS(Partner_Data!$K:$K,Partner_Data!$A:$A,Inputs!$B$6,Partner_Data!$C:$C,$A7),0))*SUMIFS(Partner_Data!$D:$D,Partner_Data!$A:$A,Inputs!$B$6,Partner_Data!$C:$C,$A7)/(SUMIFS(Partner_Data!$E:$E,Partner_Data!$A:$A,Inputs!$B$6,Partner_Data!$C:$C,$A7)*(IFERROR(SUMIFS(Partner_Data!$F:$F,Partner_Data!$A:$A,"C03",Partner_Data!$C:$C,$A7)/SUMIFS(Partner_Data!$E:$E,Partner_Data!$A:$A,"C03",Partner_Data!$C:$C,$A7),0)-$B7)),"n/a"))) -> — | F7: =IF(Inputs!$B$6="C04","—",IF(IFERROR(SUMIFS(Partner_Data!$F:$F,Partner_Data!$A:$A,"C04",Partner_Data!$C:$C,$A7)/SUMIFS(Partner_Data!$E:$E,Partner_Data!$A:$A,"C04",Partner_Data!$C:$C,$A7),0)-$B7<=0,"No gain",IFERROR((IFERROR(SUMIFS(Partner_Data!$L:$L,Partner_Data!$A:$A,"C04",Partner_Data!$C:$C,$A7)/SUMIFS(Partner_Data!$K:$K,Partner_Data!$A:$A,"C04",Partner_Data!$C:$C,$A7),0)*(1+Inputs!$B$9)-IFERROR(SUMIFS(Partner_Data!$L:$L,Partner_Data!$A:$A,Inputs!$B$6,Partner_Data!$C:$C,$A7)/SUMIFS(Partner_Data!$K:$K,Partner_Data!$A:$A,Inputs!$B$6,Partner_Data!$C:$C,$A7),0))*SUMIFS(Partner_Data!$D:$D,Partner_Data!$A:$A,Inputs!$B$6,Partner_Data!$C:$C,$A7)/(SUMIFS(Partner_Data!$E:$E,Partner_Data!$A:$A,Inputs!$B$6,Partner_Data!$C:$C,$A7)*(IFERROR(SUMIFS(Partner_Data!$F:$F,Partner_Data!$A:$A,"C04",Partner_Data!$C:$C,$A7)/SUMIFS(Partner_Data!$E:$E,Partner_Data!$A:$A,"C04",Partner_Data!$C:$C,$A7),0)-$B7)),"n/a"))) -> 67.327332 | G7: =IF(Inputs!$B$6="C05","—",IF(IFERROR(SUMIFS(Partner_Data!$F:$F,Partner_Data!$A:$A,"C05",Partner_Data!$C:$C,$A7)/SUMIFS(Partner_Data!$E:$E,Partner_Data!$A:$A,"C05",Partner_Data!$C:$C,$A7),0)-$B7<=0,"No gain",IFERROR((IFERROR(SUMIFS(Partner_Data!$L:$L,Partner_Data!$A:$A,"C05",Partner_Data!$C:$C,$A7)/SUMIFS(Partner_Data!$K:$K,Partner_Data!$A:$A,"C05",Partner_Data!$C:$C,$A7),0)*(1+Inputs!$B$9)-IFERROR(SUMIFS(Partner_Data!$L:$L,Partner_Data!$A:$A,Inputs!$B$6,Partner_Data!$C:$C,$A7)/SUMIFS(Partner_Data!$K:$K,Partner_Data!$A:$A,Inputs!$B$6,Partner_Data!$C:$C,$A7),0))*SUMIFS(Partner_Data!$D:$D,Partner_Data!$A:$A,Inputs!$B$6,Partner_Data!$C:$C,$A7)/(SUMIFS(Partner_Data!$E:$E,Partner_Data!$A:$A,Inputs!$B$6,Partner_Data!$C:$C,$A7)*(IFERROR(SUMIFS(Partner_Data!$F:$F,Partner_Data!$A:$A,"C05",Partner_Data!$C:$C,$A7)/SUMIFS(Partner_Data!$E:$E,Partner_Data!$A:$A,"C05",Partner_Data!$C:$C,$A7),0)-$B7)),"n/a"))) -> 90.982864
A8: Ajman | B8: =IFERROR(SUMIFS(Partner_Data!$F:$F,Partner_Data!$A:$A,Inputs!$B$6,Partner_Data!$C:$C,$A8)/SUMIFS(Partner_Data!$E:$E,Partner_Data!$A:$A,Inputs!$B$6,Partner_Data!$C:$C,$A8),0) -> 0.79289941 | C8: =IF(Inputs!$B$6="C01","—",IF(IFERROR(SUMIFS(Partner_Data!$F:$F,Partner_Data!$A:$A,"C01",Partner_Data!$C:$C,$A8)/SUMIFS(Partner_Data!$E:$E,Partner_Data!$A:$A,"C01",Partner_Data!$C:$C,$A8),0)-$B8<=0,"No gain",IFERROR((IFERROR(SUMIFS(Partner_Data!$L:$L,Partner_Data!$A:$A,"C01",Partner_Data!$C:$C,$A8)/SUMIFS(Partner_Data!$K:$K,Partner_Data!$A:$A,"C01",Partner_Data!$C:$C,$A8),0)*(1+Inputs!$B$9)-IFERROR(SUMIFS(Partner_Data!$L:$L,Partner_Data!$A:$A,Inputs!$B$6,Partner_Data!$C:$C,$A8)/SUMIFS(Partner_Data!$K:$K,Partner_Data!$A:$A,Inputs!$B$6,Partner_Data!$C:$C,$A8),0))*SUMIFS(Partner_Data!$D:$D,Partner_Data!$A:$A,Inputs!$B$6,Partner_Data!$C:$C,$A8)/(SUMIFS(Partner_Data!$E:$E,Partner_Data!$A:$A,Inputs!$B$6,Partner_Data!$C:$C,$A8)*(IFERROR(SUMIFS(Partner_Data!$F:$F,Partner_Data!$A:$A,"C01",Partner_Data!$C:$C,$A8)/SUMIFS(Partner_Data!$E:$E,Partner_Data!$A:$A,"C01",Partner_Data!$C:$C,$A8),0)-$B8)),"n/a"))) -> 82.358758 | D8: =IF(Inputs!$B$6="C02","—",IF(IFERROR(SUMIFS(Partner_Data!$F:$F,Partner_Data!$A:$A,"C02",Partner_Data!$C:$C,$A8)/SUMIFS(Partner_Data!$E:$E,Partner_Data!$A:$A,"C02",Partner_Data!$C:$C,$A8),0)-$B8<=0,"No gain",IFERROR((IFERROR(SUMIFS(Partner_Data!$L:$L,Partner_Data!$A:$A,"C02",Partner_Data!$C:$C,$A8)/SUMIFS(Partner_Data!$K:$K,Partner_Data!$A:$A,"C02",Partner_Data!$C:$C,$A8),0)*(1+Inputs!$B$9)-IFERROR(SUMIFS(Partner_Data!$L:$L,Partner_Data!$A:$A,Inputs!$B$6,Partner_Data!$C:$C,$A8)/SUMIFS(Partner_Data!$K:$K,Partner_Data!$A:$A,Inputs!$B$6,Partner_Data!$C:$C,$A8),0))*SUMIFS(Partner_Data!$D:$D,Partner_Data!$A:$A,Inputs!$B$6,Partner_Data!$C:$C,$A8)/(SUMIFS(Partner_Data!$E:$E,Partner_Data!$A:$A,Inputs!$B$6,Partner_Data!$C:$C,$A8)*(IFERROR(SUMIFS(Partner_Data!$F:$F,Partner_Data!$A:$A,"C02",Partner_Data!$C:$C,$A8)/SUMIFS(Partner_Data!$E:$E,Partner_Data!$A:$A,"C02",Partner_Data!$C:$C,$A8),0)-$B8)),"n/a"))) -> 133.02392 | E8: =IF(Inputs!$B$6="C03","—",IF(IFERROR(SUMIFS(Partner_Data!$F:$F,Partner_Data!$A:$A,"C03",Partner_Data!$C:$C,$A8)/SUMIFS(Partner_Data!$E:$E,Partner_Data!$A:$A,"C03",Partner_Data!$C:$C,$A8),0)-$B8<=0,"No gain",IFERROR((IFERROR(SUMIFS(Partner_Data!$L:$L,Partner_Data!$A:$A,"C03",Partner_Data!$C:$C,$A8)/SUMIFS(Partner_Data!$K:$K,Partner_Data!$A:$A,"C03",Partner_Data!$C:$C,$A8),0)*(1+Inputs!$B$9)-IFERROR(SUMIFS(Partner_Data!$L:$L,Partner_Data!$A:$A,Inputs!$B$6,Partner_Data!$C:$C,$A8)/SUMIFS(Partner_Data!$K:$K,Partner_Data!$A:$A,Inputs!$B$6,Partner_Data!$C:$C,$A8),0))*SUMIFS(Partner_Data!$D:$D,Partner_Data!$A:$A,Inputs!$B$6,Partner_Data!$C:$C,$A8)/(SUMIFS(Partner_Data!$E:$E,Partner_Data!$A:$A,Inputs!$B$6,Partner_Data!$C:$C,$A8)*(IFERROR(SUMIFS(Partner_Data!$F:$F,Partner_Data!$A:$A,"C03",Partner_Data!$C:$C,$A8)/SUMIFS(Partner_Data!$E:$E,Partner_Data!$A:$A,"C03",Partner_Data!$C:$C,$A8),0)-$B8)),"n/a"))) -> — | F8: =IF(Inputs!$B$6="C04","—",IF(IFERROR(SUMIFS(Partner_Data!$F:$F,Partner_Data!$A:$A,"C04",Partner_Data!$C:$C,$A8)/SUMIFS(Partner_Data!$E:$E,Partner_Data!$A:$A,"C04",Partner_Data!$C:$C,$A8),0)-$B8<=0,"No gain",IFERROR((IFERROR(SUMIFS(Partner_Data!$L:$L,Partner_Data!$A:$A,"C04",Partner_Data!$C:$C,$A8)/SUMIFS(Partner_Data!$K:$K,Partner_Data!$A:$A,"C04",Partner_Data!$C:$C,$A8),0)*(1+Inputs!$B$9)-IFERROR(SUMIFS(Partner_Data!$L:$L,Partner_Data!$A:$A,Inputs!$B$6,Partner_Data!$C:$C,$A8)/SUMIFS(Partner_Data!$K:$K,Partner_Data!$A:$A,Inputs!$B$6,Partner_Data!$C:$C,$A8),0))*SUMIFS(Partner_Data!$D:$D,Partner_Data!$A:$A,Inputs!$B$6,Partner_Data!$C:$C,$A8)/(SUMIFS(Partner_Data!$E:$E,Partner_Data!$A:$A,Inputs!$B$6,Partner_Data!$C:$C,$A8)*(IFERROR(SUMIFS(Partner_Data!$F:$F,Partner_Data!$A:$A,"C04",Partner_Data!$C:$C,$A8)/SUMIFS(Partner_Data!$E:$E,Partner_Data!$A:$A,"C04",Partner_Data!$C:$C,$A8),0)-$B8)),"n/a"))) -> 73.277343 | G8: =IF(Inputs!$B$6="C05","—",IF(IFERROR(SUMIFS(Partner_Data!$F:$F,Partner_Data!$A:$A,"C05",Partner_Data!$C:$C,$A8)/SUMIFS(Partner_Data!$E:$E,Partner_Data!$A:$A,"C05",Partner_Data!$C:$C,$A8),0)-$B8<=0,"No gain",IFERROR((IFERROR(SUMIFS(Partner_Data!$L:$L,Partner_Data!$A:$A,"C05",Partner_Data!$C:$C,$A8)/SUMIFS(Partner_Data!$K:$K,Partner_Data!$A:$A,"C05",Partner_Data!$C:$C,$A8),0)*(1+Inputs!$B$9)-IFERROR(SUMIFS(Partner_Data!$L:$L,Partner_Data!$A:$A,Inputs!$B$6,Partner_Data!$C:$C,$A8)/SUMIFS(Partner_Data!$K:$K,Partner_Data!$A:$A,Inputs!$B$6,Partner_Data!$C:$C,$A8),0))*SUMIFS(Partner_Data!$D:$D,Partner_Data!$A:$A,Inputs!$B$6,Partner_Data!$C:$C,$A8)/(SUMIFS(Partner_Data!$E:$E,Partner_Data!$A:$A,Inputs!$B$6,Partner_Data!$C:$C,$A8)*(IFERROR(SUMIFS(Partner_Data!$F:$F,Partner_Data!$A:$A,"C05",Partner_Data!$C:$C,$A8)/SUMIFS(Partner_Data!$E:$E,Partner_Data!$A:$A,"C05",Partner_Data!$C:$C,$A8),0)-$B8)),"n/a"))) -> 100.8393
A9: Dubai | B9: =IFERROR(SUMIFS(Partner_Data!$F:$F,Partner_Data!$A:$A,Inputs!$B$6,Partner_Data!$C:$C,$A9)/SUMIFS(Partner_Data!$E:$E,Partner_Data!$A:$A,Inputs!$B$6,Partner_Data!$C:$C,$A9),0) -> 0.79014085 | C9: =IF(Inputs!$B$6="C01","—",IF(IFERROR(SUMIFS(Partner_Data!$F:$F,Partner_Data!$A:$A,"C01",Partner_Data!$C:$C,$A9)/SUMIFS(Partner_Data!$E:$E,Partner_Data!$A:$A,"C01",Partner_Data!$C:$C,$A9),0)-$B9<=0,"No gain",IFERROR((IFERROR(SUMIFS(Partner_Data!$L:$L,Partner_Data!$A:$A,"C01",Partner_Data!$C:$C,$A9)/SUMIFS(Partner_Data!$K:$K,Partner_Data!$A:$A,"C01",Partner_Data!$C:$C,$A9),0)*(1+Inputs!$B$9)-IFERROR(SUMIFS(Partner_Data!$L:$L,Partner_Data!$A:$A,Inputs!$B$6,Partner_Data!$C:$C,$A9)/SUMIFS(Partner_Data!$K:$K,Partner_Data!$A:$A,Inputs!$B$6,Partner_Data!$C:$C,$A9),0))*SUMIFS(Partner_Data!$D:$D,Partner_Data!$A:$A,Inputs!$B$6,Partner_Data!$C:$C,$A9)/(SUMIFS(Partner_Data!$E:$E,Partner_Data!$A:$A,Inputs!$B$6,Partner_Data!$C:$C,$A9)*(IFERROR(SUMIFS(Partner_Data!$F:$F,Partner_Data!$A:$A,"C01",Partner_Data!$C:$C,$A9)/SUMIFS(Partner_Data!$E:$E,Partner_Data!$A:$A,"C01",Partner_Data!$C:$C,$A9),0)-$B9)),"n/a"))) -> 104.79831 | D9: =IF(Inputs!$B$6="C02","—",IF(IFERROR(SUMIFS(Partner_Data!$F:$F,Partner_Data!$A:$A,"C02",Partner_Data!$C:$C,$A9)/SUMIFS(Partner_Data!$E:$E,Partner_Data!$A:$A,"C02",Partner_Data!$C:$C,$A9),0)-$B9<=0,"No gain",IFERROR((IFERROR(SUMIFS(Partner_Data!$L:$L,Partner_Data!$A:$A,"C02",Partner_Data!$C:$C,$A9)/SUMIFS(Partner_Data!$K:$K,Partner_Data!$A:$A,"C02",Partner_Data!$C:$C,$A9),0)*(1+Inputs!$B$9)-IFERROR(SUMIFS(Partner_Data!$L:$L,Partner_Data!$A:$A,Inputs!$B$6,Partner_Data!$C:$C,$A9)/SUMIFS(Partner_Data!$K:$K,Partner_Data!$A:$A,Inputs!$B$6,Partner_Data!$C:$C,$A9),0))*SUMIFS(Partner_Data!$D:$D,Partner_Data!$A:$A,Inputs!$B$6,Partner_Data!$C:$C,$A9)/(SUMIFS(Partner_Data!$E:$E,Partner_Data!$A:$A,Inputs!$B$6,Partner_Data!$C:$C,$A9)*(IFERROR(SUMIFS(Partner_Data!$F:$F,Partner_Data!$A:$A,"C02",Partner_Data!$C:$C,$A9)/SUMIFS(Partner_Data!$E:$E,Partner_Data!$A:$A,"C02",Partner_Data!$C:$C,$A9),0)-$B9)),"n/a"))) -> 75.103743 | E9: =IF(Inputs!$B$6="C03","—",IF(IFERROR(SUMIFS(Partner_Data!$F:$F,Partner_Data!$A:$A,"C03",Partner_Data!$C:$C,$A9)/SUMIFS(Partner_Data!$E:$E,Partner_Data!$A:$A,"C03",Partner_Data!$C:$C,$A9),0)-$B9<=0,"No gain",IFERROR((IFERROR(SUMIFS(Partner_Data!$L:$L,Partner_Data!$A:$A,"C03",Partner_Data!$C:$C,$A9)/SUMIFS(Partner_Data!$K:$K,Partner_Data!$A:$A,"C03",Partner_Data!$C:$C,$A9),0)*(1+Inputs!$B$9)-IFERROR(SUMIFS(Partner_Data!$L:$L,Partner_Data!$A:$A,Inputs!$B$6,Partner_Data!$C:$C,$A9)/SUMIFS(Partner_Data!$K:$K,Partner_Data!$A:$A,Inputs!$B$6,Partner_Data!$C:$C,$A9),0))*SUMIFS(Partner_Data!$D:$D,Partner_Data!$A:$A,Inputs!$B$6,Partner_Data!$C:$C,$A9)/(SUMIFS(Partner_Data!$E:$E,Partner_Data!$A:$A,Inputs!$B$6,Partner_Data!$C:$C,$A9)*(IFERROR(SUMIFS(Partner_Data!$F:$F,Partner_Data!$A:$A,"C03",Partner_Data!$C:$C,$A9)/SUMIFS(Partner_Data!$E:$E,Partner_Data!$A:$A,"C03",Partner_Data!$C:$C,$A9),0)-$B9)),"n/a"))) -> — | F9: =IF(Inputs!$B$6="C04","—",IF(IFERROR(SUMIFS(Partner_Data!$F:$F,Partner_Data!$A:$A,"C04",Partner_Data!$C:$C,$A9)/SUMIFS(Partner_Data!$E:$E,Partner_Data!$A:$A,"C04",Partner_Data!$C:$C,$A9),0)-$B9<=0,"No gain",IFERROR((IFERROR(SUMIFS(Partner_Data!$L:$L,Partner_Data!$A:$A,"C04",Partner_Data!$C:$C,$A9)/SUMIFS(Partner_Data!$K:$K,Partner_Data!$A:$A,"C04",Partner_Data!$C:$C,$A9),0)*(1+Inputs!$B$9)-IFERROR(SUMIFS(Partner_Data!$L:$L,Partner_Data!$A:$A,Inputs!$B$6,Partner_Data!$C:$C,$A9)/SUMIFS(Partner_Data!$K:$K,Partner_Data!$A:$A,Inputs!$B$6,Partner_Data!$C:$C,$A9),0))*SUMIFS(Partner_Data!$D:$D,Partner_Data!$A:$A,Inputs!$B$6,Partner_Data!$C:$C,$A9)/(SUMIFS(Partner_Data!$E:$E,Partner_Data!$A:$A,Inputs!$B$6,Partner_Data!$C:$C,$A9)*(IFERROR(SUMIFS(Partner_Data!$F:$F,Partner_Data!$A:$A,"C04",Partner_Data!$C:$C,$A9)/SUMIFS(Partner_Data!$E:$E,Partner_Data!$A:$A,"C04",Partner_Data!$C:$C,$A9),0)-$B9)),"n/a"))) -> 39.200421 | G9: =IF(Inputs!$B$6="C05","—",IF(IFERROR(SUMIFS(Partner_Data!$F:$F,Partner_Data!$A:$A,"C05",Partner_Data!$C:$C,$A9)/SUMIFS(Partner_Data!$E:$E,Partner_Data!$A:$A,"C05",Partner_Data!$C:$C,$A9),0)-$B9<=0,"No gain",IFERROR((IFERROR(SUMIFS(Partner_Data!$L:$L,Partner_Data!$A:$A,"C05",Partner_Data!$C:$C,$A9)/SUMIFS(Partner_Data!$K:$K,Partner_Data!$A:$A,"C05",Partner_Data!$C:$C,$A9),0)*(1+Inputs!$B$9)-IFERROR(SUMIFS(Partner_Data!$L:$L,Partner_Data!$A:$A,Inputs!$B$6,Partner_Data!$C:$C,$A9)/SUMIFS(Partner_Data!$K:$K,Partner_Data!$A:$A,Inputs!$B$6,Partner_Data!$C:$C,$A9),0))*SUMIFS(Partner_Data!$D:$D,Partner_Data!$A:$A,Inputs!$B$6,Partner_Data!$C:$C,$A9)/(SUMIFS(Partner_Data!$E:$E,Partner_Data!$A:$A,Inputs!$B$6,Partner_Data!$C:$C,$A9)*(IFERROR(SUMIFS(Partner_Data!$F:$F,Partner_Data!$A:$A,"C05",Partner_Data!$C:$C,$A9)/SUMIFS(Partner_Data!$E:$E,Partner_Data!$A:$A,"C05",Partner_Data!$C:$C,$A9),0)-$B9)),"n/a"))) -> 92.145065
A10: Fujairah | B10: =IFERROR(SUMIFS(Partner_Data!$F:$F,Partner_Data!$A:$A,Inputs!$B$6,Partner_Data!$C:$C,$A10)/SUMIFS(Partner_Data!$E:$E,Partner_Data!$A:$A,Inputs!$B$6,Partner_Data!$C:$C,$A10),0) -> 0.71910112 | C10: =IF(Inputs!$B$6="C01","—",IF(IFERROR(SUMIFS(Partner_Data!$F:$F,Partner_Data!$A:$A,"C01",Partner_Data!$C:$C,$A10)/SUMIFS(Partner_Data!$E:$E,Partner_Data!$A:$A,"C01",Partner_Data!$C:$C,$A10),0)-$B10<=0,"No gain",IFERROR((IFERROR(SUMIFS(Partner_Data!$L:$L,Partner_Data!$A:$A,"C01",Partner_Data!$C:$C,$A10)/SUMIFS(Partner_Data!$K:$K,Partner_Data!$A:$A,"C01",Partner_Data!$C:$C,$A10),0)*(1+Inputs!$B$9)-IFERROR(SUMIFS(Partner_Data!$L:$L,Partner_Data!$A:$A,Inputs!$B$6,Partner_Data!$C:$C,$A10)/SUMIFS(Partner_Data!$K:$K,Partner_Data!$A:$A,Inputs!$B$6,Partner_Data!$C:$C,$A10),0))*SUMIFS(Partner_Data!$D:$D,Partner_Data!$A:$A,Inputs!$B$6,Partner_Data!$C:$C,$A10)/(SUMIFS(Partner_Data!$E:$E,Partner_Data!$A:$A,Inputs!$B$6,Partner_Data!$C:$C,$A10)*(IFERROR(SUMIFS(Partner_Data!$F:$F,Partner_Data!$A:$A,"C01",Partner_Data!$C:$C,$A10)/SUMIFS(Partner_Data!$E:$E,Partner_Data!$A:$A,"C01",Partner_Data!$C:$C,$A10),0)-$B10)),"n/a"))) -> 86.34282 | D10: =IF(Inputs!$B$6="C02","—",IF(IFERROR(SUMIFS(Partner_Data!$F:$F,Partner_Data!$A:$A,"C02",Partner_Data!$C:$C,$A10)/SUMIFS(Partner_Data!$E:$E,Partner_Data!$A:$A,"C02",Partner_Data!$C:$C,$A10),0)-$B10<=0,"No gain",IFERROR((IFERROR(SUMIFS(Partner_Data!$L:$L,Partner_Data!$A:$A,"C02",Partner_Data!$C:$C,$A10)/SUMIFS(Partner_Data!$K:$K,Partner_Data!$A:$A,"C02",Partner_Data!$C:$C,$A10),0)*(1+Inputs!$B$9)-IFERROR(SUMIFS(Partner_Data!$L:$L,Partner_Data!$A:$A,Inputs!$B$6,Partner_Data!$C:$C,$A10)/SUMIFS(Partner_Data!$K:$K,Partner_Data!$A:$A,Inputs!$B$6,Partner_Data!$C:$C,$A10),0))*SUMIFS(Partner_Data!$D:$D,Partner_Data!$A:$A,Inputs!$B$6,Partner_Data!$C:$C,$A10)/(SUMIFS(Partner_Data!$E:$E,Partner_Data!$A:$A,Inputs!$B$6,Partner_Data!$C:$C,$A10)*(IFERROR(SUMIFS(Partner_Data!$F:$F,Partner_Data!$A:$A,"C02",Partner_Data!$C:$C,$A10)/SUMIFS(Partner_Data!$E:$E,Partner_Data!$A:$A,"C02",Partner_Data!$C:$C,$A10),0)-$B10)),"n/a"))) -> 43.354209 | E10: =IF(Inputs!$B$6="C03","—",IF(IFERROR(SUMIFS(Partner_Data!$F:$F,Partner_Data!$A:$A,"C03",Partner_Data!$C:$C,$A10)/SUMIFS(Partner_Data!$E:$E,Partner_Data!$A:$A,"C03",Partner_Data!$C:$C,$A10),0)-$B10<=0,"No gain",IFERROR((IFERROR(SUMIFS(Partner_Data!$L:$L,Partner_Data!$A:$A,"C03",Partner_Data!$C:$C,$A10)/SUMIFS(Partner_Data!$K:$K,Partner_Data!$A:$A,"C03",Partner_Data!$C:$C,$A10),0)*(1+Inputs!$B$9)-IFERROR(SUMIFS(Partner_Data!$L:$L,Partner_Data!$A:$A,Inputs!$B$6,Partner_Data!$C:$C,$A10)/SUMIFS(Partner_Data!$K:$K,Partner_Data!$A:$A,Inputs!$B$6,Partner_Data!$C:$C,$A10),0))*SUMIFS(Partner_Data!$D:$D,Partner_Data!$A:$A,Inputs!$B$6,Partner_Data!$C:$C,$A10)/(SUMIFS(Partner_Data!$E:$E,Partner_Data!$A:$A,Inputs!$B$6,Partner_Data!$C:$C,$A10)*(IFERROR(SUMIFS(Partner_Data!$F:$F,Partner_Data!$A:$A,"C03",Partner_Data!$C:$C,$A10)/SUMIFS(Partner_Data!$E:$E,Partner_Data!$A:$A,"C03",Partner_Data!$C:$C,$A10),0)-$B10)),"n/a"))) -> — | F10: =IF(Inputs!$B$6="C04","—",IF(IFERROR(SUMIFS(Partner_Data!$F:$F,Partner_Data!$A:$A,"C04",Partner_Data!$C:$C,$A10)/SUMIFS(Partner_Data!$E:$E,Partner_Data!$A:$A,"C04",Partner_Data!$C:$C,$A10),0)-$B10<=0,"No gain",IFERROR((IFERROR(SUMIFS(Partner_Data!$L:$L,Partner_Data!$A:$A,"C04",Partner_Data!$C:$C,$A10)/SUMIFS(Partner_Data!$K:$K,Partner_Data!$A:$A,"C04",Partner_Data!$C:$C,$A10),0)*(1+Inputs!$B$9)-IFERROR(SUMIFS(Partner_Data!$L:$L,Partner_Data!$A:$A,Inputs!$B$6,Partner_Data!$C:$C,$A10)/SUMIFS(Partner_Data!$K:$K,Partner_Data!$A:$A,Inputs!$B$6,Partner_Data!$C:$C,$A10),0))*SUMIFS(Partner_Data!$D:$D,Partner_Data!$A:$A,Inputs!$B$6,Partner_Data!$C:$C,$A10)/(SUMIFS(Partner_Data!$E:$E,Partner_Data!$A:$A,Inputs!$B$6,Partner_Data!$C:$C,$A10)*(IFERROR(SUMIFS(Partner_Data!$F:$F,Partner_Data!$A:$A,"C04",Partner_Data!$C:$C,$A10)/SUMIFS(Partner_Data!$E:$E,Partner_Data!$A:$A,"C04",Partner_Data!$C:$C,$A10),0)-$B10)),"n/a"))) -> 57.409437 | G10: =IF(Inputs!$B$6="C05","—",IF(IFERROR(SUMIFS(Partner_Data!$F:$F,Partner_Data!$A:$A,"C05",Partner_Data!$C:$C,$A10)/SUMIFS(Partner_Data!$E:$E,Partner_Data!$A:$A,"C05",Partner_Data!$C:$C,$A10),0)-$B10<=0,"No gain",IFERROR((IFERROR(SUMIFS(Partner_Data!$L:$L,Partner_Data!$A:$A,"C05",Partner_Data!$C:$C,$A10)/SUMIFS(Partner_Data!$K:$K,Partner_Data!$A:$A,"C05",Partner_Data!$C:$C,$A10),0)*(1+Inputs!$B$9)-IFERROR(SUMIFS(Partner_Data!$L:$L,Partner_Data!$A:$A,Inputs!$B$6,Partner_Data!$C:$C,$A10)/SUMIFS(Partner_Data!$K:$K,Partner_Data!$A:$A,Inputs!$B$6,Partner_Data!$C:$C,$A10),0))*SUMIFS(Partner_Data!$D:$D,Partner_Data!$A:$A,Inputs!$B$6,Partner_Data!$C:$C,$A10)/(SUMIFS(Partner_Data!$E:$E,Partner_Data!$A:$A,Inputs!$B$6,Partner_Data!$C:$C,$A10)*(IFERROR(SUMIFS(Partner_Data!$F:$F,Partner_Data!$A:$A,"C05",Partner_Data!$C:$C,$A10)/SUMIFS(Partner_Data!$E:$E,Partner_Data!$A:$A,"C05",Partner_Data!$C:$C,$A10),0)-$B10)),"n/a"))) -> 28.132658
A11: Ras Al Khaimah | B11: =IFERROR(SUMIFS(Partner_Data!$F:$F,Partner_Data!$A:$A,Inputs!$B$6,Partner_Data!$C:$C,$A11)/SUMIFS(Partner_Data!$E:$E,Partner_Data!$A:$A,Inputs!$B$6,Partner_Data!$C:$C,$A11),0) -> 0.69285714 | C11: =IF(Inputs!$B$6="C01","—",IF(IFERROR(SUMIFS(Partner_Data!$F:$F,Partner_Data!$A:$A,"C01",Partner_Data!$C:$C,$A11)/SUMIFS(Partner_Data!$E:$E,Partner_Data!$A:$A,"C01",Partner_Data!$C:$C,$A11),0)-$B11<=0,"No gain",IFERROR((IFERROR(SUMIFS(Partner_Data!$L:$L,Partner_Data!$A:$A,"C01",Partner_Data!$C:$C,$A11)/SUMIFS(Partner_Data!$K:$K,Partner_Data!$A:$A,"C01",Partner_Data!$C:$C,$A11),0)*(1+Inputs!$B$9)-IFERROR(SUMIFS(Partner_Data!$L:$L,Partner_Data!$A:$A,Inputs!$B$6,Partner_Data!$C:$C,$A11)/SUMIFS(Partner_Data!$K:$K,Partner_Data!$A:$A,Inputs!$B$6,Partner_Data!$C:$C,$A11),0))*SUMIFS(Partner_Data!$D:$D,Partner_Data!$A:$A,Inputs!$B$6,Partner_Data!$C:$C,$A11)/(SUMIFS(Partner_Data!$E:$E,Partner_Data!$A:$A,Inputs!$B$6,Partner_Data!$C:$C,$A11)*(IFERROR(SUMIFS(Partner_Data!$F:$F,Partner_Data!$A:$A,"C01",Partner_Data!$C:$C,$A11)/SUMIFS(Partner_Data!$E:$E,Partner_Data!$A:$A,"C01",Partner_Data!$C:$C,$A11),0)-$B11)),"n/a"))) -> 54.374117 | D11: =IF(Inputs!$B$6="C02","—",IF(IFERROR(SUMIFS(Partner_Data!$F:$F,Partner_Data!$A:$A,"C02",Partner_Data!$C:$C,$A11)/SUMIFS(Partner_Data!$E:$E,Partner_Data!$A:$A,"C02",Partner_Data!$C:$C,$A11),0)-$B11<=0,"No gain",IFERROR((IFERROR(SUMIFS(Partner_Data!$L:$L,Partner_Data!$A:$A,"C02",Partner_Data!$C:$C,$A11)/SUMIFS(Partner_Data!$K:$K,Partner_Data!$A:$A,"C02",Partner_Data!$C:$C,$A11),0)*(1+Inputs!$B$9)-IFERROR(SUMIFS(Partner_Data!$L:$L,Partner_Data!$A:$A,Inputs!$B$6,Partner_Data!$C:$C,$A11)/SUMIFS(Partner_Data!$K:$K,Partner_Data!$A:$A,Inputs!$B$6,Partner_Data!$C:$C,$A11),0))*SUMIFS(Partner_Data!$D:$D,Partner_Data!$A:$A,Inputs!$B$6,Partner_Data!$C:$C,$A11)/(SUMIFS(Partner_Data!$E:$E,Partner_Data!$A:$A,Inputs!$B$6,Partner_Data!$C:$C,$A11)*(IFERROR(SUMIFS(Partner_Data!$F:$F,Partner_Data!$A:$A,"C02",Partner_Data!$C:$C,$A11)/SUMIFS(Partner_Data!$E:$E,Partner_Data!$A:$A,"C02",Partner_Data!$C:$C,$A11),0)-$B11)),"n/a"))) -> 28.144348 | E11: =IF(Inputs!$B$6="C03","—",IF(IFERROR(SUMIFS(Partner_Data!$F:$F,Partner_Data!$A:$A,"C03",Partner_Data!$C:$C,$A11)/SUMIFS(Partner_Data!$E:$E,Partner_Data!$A:$A,"C03",Partner_Data!$C:$C,$A11),0)-$B11<=0,"No gain",IFERROR((IFERROR(SUMIFS(Partner_Data!$L:$L,Partner_Data!$A:$A,"C03",Partner_Data!$C:$C,$A11)/SUMIFS(Partner_Data!$K:$K,Partner_Data!$A:$A,"C03",Partner_Data!$C:$C,$A11),0)*(1+Inputs!$B$9)-IFERROR(SUMIFS(Partner_Data!$L:$L,Partner_Data!$A:$A,Inputs!$B$6,Partner_Data!$C:$C,$A11)/SUMIFS(Partner_Data!$K:$K,Partner_Data!$A:$A,Inputs!$B$6,Partner_Data!$C:$C,$A11),0))*SUMIFS(Partner_Data!$D:$D,Partner_Data!$A:$A,Inputs!$B$6,Partner_Data!$C:$C,$A11)/(SUMIFS(Partner_Data!$E:$E,Partner_Data!$A:$A,Inputs!$B$6,Partner_Data!$C:$C,$A11)*(IFERROR(SUMIFS(Partner_Data!$F:$F,Partner_Data!$A:$A,"C03",Partner_Data!$C:$C,$A11)/SUMIFS(Partner_Data!$E:$E,Partner_Data!$A:$A,"C03",Partner_Data!$C:$C,$A11),0)-$B11)),"n/a"))) -> — | F11: =IF(Inputs!$B$6="C04","—",IF(IFERROR(SUMIFS(Partner_Data!$F:$F,Partner_Data!$A:$A,"C04",Partner_Data!$C:$C,$A11)/SUMIFS(Partner_Data!$E:$E,Partner_Data!$A:$A,"C04",Partner_Data!$C:$C,$A11),0)-$B11<=0,"No gain",IFERROR((IFERROR(SUMIFS(Partner_Data!$L:$L,Partner_Data!$A:$A,"C04",Partner_Data!$C:$C,$A11)/SUMIFS(Partner_Data!$K:$K,Partner_Data!$A:$A,"C04",Partner_Data!$C:$C,$A11),0)*(1+Inputs!$B$9)-IFERROR(SUMIFS(Partner_Data!$L:$L,Partner_Data!$A:$A,Inputs!$B$6,Partner_Data!$C:$C,$A11)/SUMIFS(Partner_Data!$K:$K,Partner_Data!$A:$A,Inputs!$B$6,Partner_Data!$C:$C,$A11),0))*SUMIFS(Partner_Data!$D:$D,Partner_Data!$A:$A,Inputs!$B$6,Partner_Data!$C:$C,$A11)/(SUMIFS(Partner_Data!$E:$E,Partner_Data!$A:$A,Inputs!$B$6,Partner_Data!$C:$C,$A11)*(IFERROR(SUMIFS(Partner_Data!$F:$F,Partner_Data!$A:$A,"C04",Partner_Data!$C:$C,$A11)/SUMIFS(Partner_Data!$E:$E,Partner_Data!$A:$A,"C04",Partner_Data!$C:$C,$A11),0)-$B11)),"n/a"))) -> 38.180519 | G11: =IF(Inputs!$B$6="C05","—",IF(IFERROR(SUMIFS(Partner_Data!$F:$F,Partner_Data!$A:$A,"C05",Partner_Data!$C:$C,$A11)/SUMIFS(Partner_Data!$E:$E,Partner_Data!$A:$A,"C05",Partner_Data!$C:$C,$A11),0)-$B11<=0,"No gain",IFERROR((IFERROR(SUMIFS(Partner_Data!$L:$L,Partner_Data!$A:$A,"C05",Partner_Data!$C:$C,$A11)/SUMIFS(Partner_Data!$K:$K,Partner_Data!$A:$A,"C05",Partner_Data!$C:$C,$A11),0)*(1+Inputs!$B$9)-IFERROR(SUMIFS(Partner_Data!$L:$L,Partner_Data!$A:$A,Inputs!$B$6,Partner_Data!$C:$C,$A11)/SUMIFS(Partner_Data!$K:$K,Partner_Data!$A:$A,Inputs!$B$6,Partner_Data!$C:$C,$A11),0))*SUMIFS(Partner_Data!$D:$D,Partner_Data!$A:$A,Inputs!$B$6,Partner_Data!$C:$C,$A11)/(SUMIFS(Partner_Data!$E:$E,Partner_Data!$A:$A,Inputs!$B$6,Partner_Data!$C:$C,$A11)*(IFERROR(SUMIFS(Partner_Data!$F:$F,Partner_Data!$A:$A,"C05",Partner_Data!$C:$C,$A11)/SUMIFS(Partner_Data!$E:$E,Partner_Data!$A:$A,"C05",Partner_Data!$C:$C,$A11),0)-$B11)),"n/a"))) -> 40.956565
A12: Sharjah | B12: =IFERROR(SUMIFS(Partner_Data!$F:$F,Partner_Data!$A:$A,Inputs!$B$6,Partner_Data!$C:$C,$A12)/SUMIFS(Partner_Data!$E:$E,Partner_Data!$A:$A,Inputs!$B$6,Partner_Data!$C:$C,$A12),0) -> 0.80178174 | C12: =IF(Inputs!$B$6="C01","—",IF(IFERROR(SUMIFS(Partner_Data!$F:$F,Partner_Data!$A:$A,"C01",Partner_Data!$C:$C,$A12)/SUMIFS(Partner_Data!$E:$E,Partner_Data!$A:$A,"C01",Partner_Data!$C:$C,$A12),0)-$B12<=0,"No gain",IFERROR((IFERROR(SUMIFS(Partner_Data!$L:$L,Partner_Data!$A:$A,"C01",Partner_Data!$C:$C,$A12)/SUMIFS(Partner_Data!$K:$K,Partner_Data!$A:$A,"C01",Partner_Data!$C:$C,$A12),0)*(1+Inputs!$B$9)-IFERROR(SUMIFS(Partner_Data!$L:$L,Partner_Data!$A:$A,Inputs!$B$6,Partner_Data!$C:$C,$A12)/SUMIFS(Partner_Data!$K:$K,Partner_Data!$A:$A,Inputs!$B$6,Partner_Data!$C:$C,$A12),0))*SUMIFS(Partner_Data!$D:$D,Partner_Data!$A:$A,Inputs!$B$6,Partner_Data!$C:$C,$A12)/(SUMIFS(Partner_Data!$E:$E,Partner_Data!$A:$A,Inputs!$B$6,Partner_Data!$C:$C,$A12)*(IFERROR(SUMIFS(Partner_Data!$F:$F,Partner_Data!$A:$A,"C01",Partner_Data!$C:$C,$A12)/SUMIFS(Partner_Data!$E:$E,Partner_Data!$A:$A,"C01",Partner_Data!$C:$C,$A12),0)-$B12)),"n/a"))) -> 135.42293 | D12: =IF(Inputs!$B$6="C02","—",IF(IFERROR(SUMIFS(Partner_Data!$F:$F,Partner_Data!$A:$A,"C02",Partner_Data!$C:$C,$A12)/SUMIFS(Partner_Data!$E:$E,Partner_Data!$A:$A,"C02",Partner_Data!$C:$C,$A12),0)-$B12<=0,"No gain",IFERROR((IFERROR(SUMIFS(Partner_Data!$L:$L,Partner_Data!$A:$A,"C02",Partner_Data!$C:$C,$A12)/SUMIFS(Partner_Data!$K:$K,Partner_Data!$A:$A,"C02",Partner_Data!$C:$C,$A12),0)*(1+Inputs!$B$9)-IFERROR(SUMIFS(Partner_Data!$L:$L,Partner_Data!$A:$A,Inputs!$B$6,Partner_Data!$C:$C,$A12)/SUMIFS(Partner_Data!$K:$K,Partner_Data!$A:$A,Inputs!$B$6,Partner_Data!$C:$C,$A12),0))*SUMIFS(Partner_Data!$D:$D,Partner_Data!$A:$A,Inputs!$B$6,Partner_Data!$C:$C,$A12)/(SUMIFS(Partner_Data!$E:$E,Partner_Data!$A:$A,Inputs!$B$6,Partner_Data!$C:$C,$A12)*(IFERROR(SUMIFS(Partner_Data!$F:$F,Partner_Data!$A:$A,"C02",Partner_Data!$C:$C,$A12)/SUMIFS(Partner_Data!$E:$E,Partner_Data!$A:$A,"C02",Partner_Data!$C:$C,$A12),0)-$B12)),"n/a"))) -> 81.39326 | E12: =IF(Inputs!$B$6="C03","—",IF(IFERROR(SUMIFS(Partner_Data!$F:$F,Partner_Data!$A:$A,"C03",Partner_Data!$C:$C,$A12)/SUMIFS(Partner_Data!$E:$E,Partner_Data!$A:$A,"C03",Partner_Data!$C:$C,$A12),0)-$B12<=0,"No gain",IFERROR((IFERROR(SUMIFS(Partner_Data!$L:$L,Partner_Data!$A:$A,"C03",Partner_Data!$C:$C,$A12)/SUMIFS(Partner_Data!$K:$K,Partner_Data!$A:$A,"C03",Partner_Data!$C:$C,$A12),0)*(1+Inputs!$B$9)-IFERROR(SUMIFS(Partner_Data!$L:$L,Partner_Data!$A:$A,Inputs!$B$6,Partner_Data!$C:$C,$A12)/SUMIFS(Partner_Data!$K:$K,Partner_Data!$A:$A,Inputs!$B$6,Partner_Data!$C:$C,$A12),0))*SUMIFS(Partner_Data!$D:$D,Partner_Data!$A:$A,Inputs!$B$6,Partner_Data!$C:$C,$A12)/(SUMIFS(Partner_Data!$E:$E,Partner_Data!$A:$A,Inputs!$B$6,Partner_Data!$C:$C,$A12)*(IFERROR(SUMIFS(Partner_Data!$F:$F,Partner_Data!$A:$A,"C03",Partner_Data!$C:$C,$A12)/SUMIFS(Partner_Data!$E:$E,Partner_Data!$A:$A,"C03",Partner_Data!$C:$C,$A12),0)-$B12)),"n/a"))) -> — | F12: =IF(Inputs!$B$6="C04","—",IF(IFERROR(SUMIFS(Partner_Data!$F:$F,Partner_Data!$A:$A,"C04",Partner_Data!$C:$C,$A12)/SUMIFS(Partner_Data!$E:$E,Partner_Data!$A:$A,"C04",Partner_Data!$C:$C,$A12),0)-$B12<=0,"No gain",IFERROR((IFERROR(SUMIFS(Partner_Data!$L:$L,Partner_Data!$A:$A,"C04",Partner_Data!$C:$C,$A12)/SUMIFS(Partner_Data!$K:$K,Partner_Data!$A:$A,"C04",Partner_Data!$C:$C,$A12),0)*(1+Inputs!$B$9)-IFERROR(SUMIFS(Partner_Data!$L:$L,Partner_Data!$A:$A,Inputs!$B$6,Partner_Data!$C:$C,$A12)/SUMIFS(Partner_Data!$K:$K,Partner_Data!$A:$A,Inputs!$B$6,Partner_Data!$C:$C,$A12),0))*SUMIFS(Partner_Data!$D:$D,Partner_Data!$A:$A,Inputs!$B$6,Partner_Data!$C:$C,$A12)/(SUMIFS(Partner_Data!$E:$E,Partner_Data!$A:$A,Inputs!$B$6,Partner_Data!$C:$C,$A12)*(IFERROR(SUMIFS(Partner_Data!$F:$F,Partner_Data!$A:$A,"C04",Partner_Data!$C:$C,$A12)/SUMIFS(Partner_Data!$E:$E,Partner_Data!$A:$A,"C04",Partner_Data!$C:$C,$A12),0)-$B12)),"n/a"))) -> 2278.7114 | G12: =IF(Inputs!$B$6="C05","—",IF(IFERROR(SUMIFS(Partner_Data!$F:$F,Partner_Data!$A:$A,"C05",Partner_Data!$C:$C,$A12)/SUMIFS(Partner_Data!$E:$E,Partner_Data!$A:$A,"C05",Partner_Data!$C:$C,$A12),0)-$B12<=0,"No gain",IFERROR((IFERROR(SUMIFS(Partner_Data!$L:$L,Partner_Data!$A:$A,"C05",Partner_Data!$C:$C,$A12)/SUMIFS(Partner_Data!$K:$K,Partner_Data!$A:$A,"C05",Partner_Data!$C:$C,$A12),0)*(1+Inputs!$B$9)-IFERROR(SUMIFS(Partner_Data!$L:$L,Partner_Data!$A:$A,Inputs!$B$6,Partner_Data!$C:$C,$A12)/SUMIFS(Partner_Data!$K:$K,Partner_Data!$A:$A,Inputs!$B$6,Partner_Data!$C:$C,$A12),0))*SUMIFS(Partner_Data!$D:$D,Partner_Data!$A:$A,Inputs!$B$6,Partner_Data!$C:$C,$A12)/(SUMIFS(Partner_Data!$E:$E,Partner_Data!$A:$A,Inputs!$B$6,Partner_Data!$C:$C,$A12)*(IFERROR(SUMIFS(Partner_Data!$F:$F,Partner_Data!$A:$A,"C05",Partner_Data!$C:$C,$A12)/SUMIFS(Partner_Data!$E:$E,Partner_Data!$A:$A,"C05",Partner_Data!$C:$C,$A12),0)-$B12)),"n/a"))) -> 123.50422
A13: Umm Al Quwain | B13: =IFERROR(SUMIFS(Partner_Data!$F:$F,Partner_Data!$A:$A,Inputs!$B$6,Partner_Data!$C:$C,$A13)/SUMIFS(Partner_Data!$E:$E,Partner_Data!$A:$A,Inputs!$B$6,Partner_Data!$C:$C,$A13),0) -> 0.83333333 | C13: =IF(Inputs!$B$6="C01","—",IF(IFERROR(SUMIFS(Partner_Data!$F:$F,Partner_Data!$A:$A,"C01",Partner_Data!$C:$C,$A13)/SUMIFS(Partner_Data!$E:$E,Partner_Data!$A:$A,"C01",Partner_Data!$C:$C,$A13),0)-$B13<=0,"No gain",IFERROR((IFERROR(SUMIFS(Partner_Data!$L:$L,Partner_Data!$A:$A,"C01",Partner_Data!$C:$C,$A13)/SUMIFS(Partner_Data!$K:$K,Partner_Data!$A:$A,"C01",Partner_Data!$C:$C,$A13),0)*(1+Inputs!$B$9)-IFERROR(SUMIFS(Partner_Data!$L:$L,Partner_Data!$A:$A,Inputs!$B$6,Partner_Data!$C:$C,$A13)/SUMIFS(Partner_Data!$K:$K,Partner_Data!$A:$A,Inputs!$B$6,Partner_Data!$C:$C,$A13),0))*SUMIFS(Partner_Data!$D:$D,Partner_Data!$A:$A,Inputs!$B$6,Partner_Data!$C:$C,$A13)/(SUMIFS(Partner_Data!$E:$E,Partner_Data!$A:$A,Inputs!$B$6,Partner_Data!$C:$C,$A13)*(IFERROR(SUMIFS(Partner_Data!$F:$F,Partner_Data!$A:$A,"C01",Partner_Data!$C:$C,$A13)/SUMIFS(Partner_Data!$E:$E,Partner_Data!$A:$A,"C01",Partner_Data!$C:$C,$A13),0)-$B13)),"n/a"))) -> 214.53407 | D13: =IF(Inputs!$B$6="C02","—",IF(IFERROR(SUMIFS(Partner_Data!$F:$F,Partner_Data!$A:$A,"C02",Partner_Data!$C:$C,$A13)/SUMIFS(Partner_Data!$E:$E,Partner_Data!$A:$A,"C02",Partner_Data!$C:$C,$A13),0)-$B13<=0,"No gain",IFERROR((IFERROR(SUMIFS(Partner_Data!$L:$L,Partner_Data!$A:$A,"C02",Partner_Data!$C:$C,$A13)/SUMIFS(Partner_Data!$K:$K,Partner_Data!$A:$A,"C02",Partner_Data!$C:$C,$A13),0)*(1+Inputs!$B$9)-IFERROR(SUMIFS(Partner_Data!$L:$L,Partner_Data!$A:$A,Inputs!$B$6,Partner_Data!$C:$C,$A13)/SUMIFS(Partner_Data!$K:$K,Partner_Data!$A:$A,Inputs!$B$6,Partner_Data!$C:$C,$A13),0))*SUMIFS(Partner_Data!$D:$D,Partner_Data!$A:$A,Inputs!$B$6,Partner_Data!$C:$C,$A13)/(SUMIFS(Partner_Data!$E:$E,Partner_Data!$A:$A,Inputs!$B$6,Partner_Data!$C:$C,$A13)*(IFERROR(SUMIFS(Partner_Data!$F:$F,Partner_Data!$A:$A,"C02",Partner_Data!$C:$C,$A13)/SUMIFS(Partner_Data!$E:$E,Partner_Data!$A:$A,"C02",Partner_Data!$C:$C,$A13),0)-$B13)),"n/a"))) -> 110.89231 | E13: =IF(Inputs!$B$6="C03","—",IF(IFERROR(SUMIFS(Partner_Data!$F:$F,Partner_Data!$A:$A,"C03",Partner_Data!$C:$C,$A13)/SUMIFS(Partner_Data!$E:$E,Partner_Data!$A:$A,"C03",Partner_Data!$C:$C,$A13),0)-$B13<=0,"No gain",IFERROR((IFERROR(SUMIFS(Partner_Data!$L:$L,Partner_Data!$A:$A,"C03",Partner_Data!$C:$C,$A13)/SUMIFS(Partner_Data!$K:$K,Partner_Data!$A:$A,"C03",Partner_Data!$C:$C,$A13),0)*(1+Inputs!$B$9)-IFERROR(SUMIFS(Partner_Data!$L:$L,Partner_Data!$A:$A,Inputs!$B$6,Partner_Data!$C:$C,$A13)/SUMIFS(Partner_Data!$K:$K,Partner_Data!$A:$A,Inputs!$B$6,Partner_Data!$C:$C,$A13),0))*SUMIFS(Partner_Data!$D:$D,Partner_Data!$A:$A,Inputs!$B$6,Partner_Data!$C:$C,$A13)/(SUMIFS(Partner_Data!$E:$E,Partner_Data!$A:$A,Inputs!$B$6,Partner_Data!$C:$C,$A13)*(IFERROR(SUMIFS(Partner_Data!$F:$F,Partner_Data!$A:$A,"C03",Partner_Data!$C:$C,$A13)/SUMIFS(Partner_Data!$E:$E,Partner_Data!$A:$A,"C03",Partner_Data!$C:$C,$A13),0)-$B13)),"n/a"))) -> — | F13: =IF(Inputs!$B$6="C04","—",IF(IFERROR(SUMIFS(Partner_Data!$F:$F,Partner_Data!$A:$A,"C04",Partner_Data!$C:$C,$A13)/SUMIFS(Partner_Data!$E:$E,Partner_Data!$A:$A,"C04",Partner_Data!$C:$C,$A13),0)-$B13<=0,"No gain",IFERROR((IFERROR(SUMIFS(Partner_Data!$L:$L,Partner_Data!$A:$A,"C04",Partner_Data!$C:$C,$A13)/SUMIFS(Partner_Data!$K:$K,Partner_Data!$A:$A,"C04",Partner_Data!$C:$C,$A13),0)*(1+Inputs!$B$9)-IFERROR(SUMIFS(Partner_Data!$L:$L,Partner_Data!$A:$A,Inputs!$B$6,Partner_Data!$C:$C,$A13)/SUMIFS(Partner_Data!$K:$K,Partner_Data!$A:$A,Inputs!$B$6,Partner_Data!$C:$C,$A13),0))*SUMIFS(Partner_Data!$D:$D,Partner_Data!$A:$A,Inputs!$B$6,Partner_Data!$C:$C,$A13)/(SUMIFS(Partner_Data!$E:$E,Partner_Data!$A:$A,Inputs!$B$6,Partner_Data!$C:$C,$A13)*(IFERROR(SUMIFS(Partner_Data!$F:$F,Partner_Data!$A:$A,"C04",Partner_Data!$C:$C,$A13)/SUMIFS(Partner_Data!$E:$E,Partner_Data!$A:$A,"C04",Partner_Data!$C:$C,$A13),0)-$B13)),"n/a"))) -> 1109.6583 | G13: =IF(Inputs!$B$6="C05","—",IF(IFERROR(SUMIFS(Partner_Data!$F:$F,Partner_Data!$A:$A,"C05",Partner_Data!$C:$C,$A13)/SUMIFS(Partner_Data!$E:$E,Partner_Data!$A:$A,"C05",Partner_Data!$C:$C,$A13),0)-$B13<=0,"No gain",IFERROR((IFERROR(SUMIFS(Partner_Data!$L:$L,Partner_Data!$A:$A,"C05",Partner_Data!$C:$C,$A13)/SUMIFS(Partner_Data!$K:$K,Partner_Data!$A:$A,"C05",Partner_Data!$C:$C,$A13),0)*(1+Inputs!$B$9)-IFERROR(SUMIFS(Partner_Data!$L:$L,Partner_Data!$A:$A,Inputs!$B$6,Partner_Data!$C:$C,$A13)/SUMIFS(Partner_Data!$K:$K,Partner_Data!$A:$A,Inputs!$B$6,Partner_Data!$C:$C,$A13),0))*SUMIFS(Partner_Data!$D:$D,Partner_Data!$A:$A,Inputs!$B$6,Partner_Data!$C:$C,$A13)/(SUMIFS(Partner_Data!$E:$E,Partner_Data!$A:$A,Inputs!$B$6,Partner_Data!$C:$C,$A13)*(IFERROR(SUMIFS(Partner_Data!$F:$F,Partner_Data!$A:$A,"C05",Partner_Data!$C:$C,$A13)/SUMIFS(Partner_Data!$E:$E,Partner_Data!$A:$A,"C05",Partner_Data!$C:$C,$A13),0)-$B13)),"n/a"))) -> 248.52194
A14: All emirates | B14: =IFERROR(SUMIFS(Partner_Data!$F:$F,Partner_Data!$A:$A,Inputs!$B$6,Partner_Data!$C:$C,$A14)/SUMIFS(Partner_Data!$E:$E,Partner_Data!$A:$A,Inputs!$B$6,Partner_Data!$C:$C,$A14),0) -> 0.78468131 | C14: =IF(Inputs!$B$6="C01","—",IF(IFERROR(SUMIFS(Partner_Data!$F:$F,Partner_Data!$A:$A,"C01",Partner_Data!$C:$C,$A14)/SUMIFS(Partner_Data!$E:$E,Partner_Data!$A:$A,"C01",Partner_Data!$C:$C,$A14),0)-$B14<=0,"No gain",IFERROR((IFERROR(SUMIFS(Partner_Data!$L:$L,Partner_Data!$A:$A,"C01",Partner_Data!$C:$C,$A14)/SUMIFS(Partner_Data!$K:$K,Partner_Data!$A:$A,"C01",Partner_Data!$C:$C,$A14),0)*(1+Inputs!$B$9)-IFERROR(SUMIFS(Partner_Data!$L:$L,Partner_Data!$A:$A,Inputs!$B$6,Partner_Data!$C:$C,$A14)/SUMIFS(Partner_Data!$K:$K,Partner_Data!$A:$A,Inputs!$B$6,Partner_Data!$C:$C,$A14),0))*SUMIFS(Partner_Data!$D:$D,Partner_Data!$A:$A,Inputs!$B$6,Partner_Data!$C:$C,$A14)/(SUMIFS(Partner_Data!$E:$E,Partner_Data!$A:$A,Inputs!$B$6,Partner_Data!$C:$C,$A14)*(IFERROR(SUMIFS(Partner_Data!$F:$F,Partner_Data!$A:$A,"C01",Partner_Data!$C:$C,$A14)/SUMIFS(Partner_Data!$E:$E,Partner_Data!$A:$A,"C01",Partner_Data!$C:$C,$A14),0)-$B14)),"n/a"))) -> 100.66935 | D14: =IF(Inputs!$B$6="C02","—",IF(IFERROR(SUMIFS(Partner_Data!$F:$F,Partner_Data!$A:$A,"C02",Partner_Data!$C:$C,$A14)/SUMIFS(Partner_Data!$E:$E,Partner_Data!$A:$A,"C02",Partner_Data!$C:$C,$A14),0)-$B14<=0,"No gain",IFERROR((IFERROR(SUMIFS(Partner_Data!$L:$L,Partner_Data!$A:$A,"C02",Partner_Data!$C:$C,$A14)/SUMIFS(Partner_Data!$K:$K,Partner_Data!$A:$A,"C02",Partner_Data!$C:$C,$A14),0)*(1+Inputs!$B$9)-IFERROR(SUMIFS(Partner_Data!$L:$L,Partner_Data!$A:$A,Inputs!$B$6,Partner_Data!$C:$C,$A14)/SUMIFS(Partner_Data!$K:$K,Partner_Data!$A:$A,Inputs!$B$6,Partner_Data!$C:$C,$A14),0))*SUMIFS(Partner_Data!$D:$D,Partner_Data!$A:$A,Inputs!$B$6,Partner_Data!$C:$C,$A14)/(SUMIFS(Partner_Data!$E:$E,Partner_Data!$A:$A,Inputs!$B$6,Partner_Data!$C:$C,$A14)*(IFERROR(SUMIFS(Partner_Data!$F:$F,Partner_Data!$A:$A,"C02",Partner_Data!$C:$C,$A14)/SUMIFS(Partner_Data!$E:$E,Partner_Data!$A:$A,"C02",Partner_Data!$C:$C,$A14),0)-$B14)),"n/a"))) -> 69.834441 | E14: =IF(Inputs!$B$6="C03","—",IF(IFERROR(SUMIFS(Partner_Data!$F:$F,Partner_Data!$A:$A,"C03",Partner_Data!$C:$C,$A14)/SUMIFS(Partner_Data!$E:$E,Partner_Data!$A:$A,"C03",Partner_Data!$C:$C,$A14),0)-$B14<=0,"No gain",IFERROR((IFERROR(SUMIFS(Partner_Data!$L:$L,Partner_Data!$A:$A,"C03",Partner_Data!$C:$C,$A14)/SUMIFS(Partner_Data!$K:$K,Partner_Data!$A:$A,"C03",Partner_Data!$C:$C,$A14),0)*(1+Inputs!$B$9)-IFERROR(SUMIFS(Partner_Data!$L:$L,Partner_Data!$A:$A,Inputs!$B$6,Partner_Data!$C:$C,$A14)/SUMIFS(Partner_Data!$K:$K,Partner_Data!$A:$A,Inputs!$B$6,Partner_Data!$C:$C,$A14),0))*SUMIFS(Partner_Data!$D:$D,Partner_Data!$A:$A,Inputs!$B$6,Partner_Data!$C:$C,$A14)/(SUMIFS(Partner_Data!$E:$E,Partner_Data!$A:$A,Inputs!$B$6,Partner_Data!$C:$C,$A14)*(IFERROR(SUMIFS(Partner_Data!$F:$F,Partner_Data!$A:$A,"C03",Partner_Data!$C:$C,$A14)/SUMIFS(Partner_Data!$E:$E,Partner_Data!$A:$A,"C03",Partner_Data!$C:$C,$A14),0)-$B14)),"n/a"))) -> — | F14: =IF(Inputs!$B$6="C04","—",IF(IFERROR(SUMIFS(Partner_Data!$F:$F,Partner_Data!$A:$A,"C04",Partner_Data!$C:$C,$A14)/SUMIFS(Partner_Data!$E:$E,Partner_Data!$A:$A,"C04",Partner_Data!$C:$C,$A14),0)-$B14<=0,"No gain",IFERROR((IFERROR(SUMIFS(Partner_Data!$L:$L,Partner_Data!$A:$A,"C04",Partner_Data!$C:$C,$A14)/SUMIFS(Partner_Data!$K:$K,Partner_Data!$A:$A,"C04",Partner_Data!$C:$C,$A14),0)*(1+Inputs!$B$9)-IFERROR(SUMIFS(Partner_Data!$L:$L,Partner_Data!$A:$A,Inputs!$B$6,Partner_Data!$C:$C,$A14)/SUMIFS(Partner_Data!$K:$K,Partner_Data!$A:$A,Inputs!$B$6,Partner_Data!$C:$C,$A14),0))*SUMIFS(Partner_Data!$D:$D,Partner_Data!$A:$A,Inputs!$B$6,Partner_Data!$C:$C,$A14)/(SUMIFS(Partner_Data!$E:$E,Partner_Data!$A:$A,Inputs!$B$6,Partner_Data!$C:$C,$A14)*(IFERROR(SUMIFS(Partner_Data!$F:$F,Partner_Data!$A:$A,"C04",Partner_Data!$C:$C,$A14)/SUMIFS(Partner_Data!$E:$E,Partner_Data!$A:$A,"C04",Partner_Data!$C:$C,$A14),0)-$B14)),"n/a"))) -> 68.879365 | G14: =IF(Inputs!$B$6="C05","—",IF(IFERROR(SUMIFS(Partner_Data!$F:$F,Partner_Data!$A:$A,"C05",Partner_Data!$C:$C,$A14)/SUMIFS(Partner_Data!$E:$E,Partner_Data!$A:$A,"C05",Partner_Data!$C:$C,$A14),0)-$B14<=0,"No gain",IFERROR((IFERROR(SUMIFS(Partner_Data!$L:$L,Partner_Data!$A:$A,"C05",Partner_Data!$C:$C,$A14)/SUMIFS(Partner_Data!$K:$K,Partner_Data!$A:$A,"C05",Partner_Data!$C:$C,$A14),0)*(1+Inputs!$B$9)-IFERROR(SUMIFS(Partner_Data!$L:$L,Partner_Data!$A:$A,Inputs!$B$6,Partner_Data!$C:$C,$A14)/SUMIFS(Partner_Data!$K:$K,Partner_Data!$A:$A,Inputs!$B$6,Partner_Data!$C:$C,$A14),0))*SUMIFS(Partner_Data!$D:$D,Partner_Data!$A:$A,Inputs!$B$6,Partner_Data!$C:$C,$A14)/(SUMIFS(Partner_Data!$E:$E,Partner_Data!$A:$A,Inputs!$B$6,Partner_Data!$C:$C,$A14)*(IFERROR(SUMIFS(Partner_Data!$F:$F,Partner_Data!$A:$A,"C05",Partner_Data!$C:$C,$A14)/SUMIFS(Partner_Data!$E:$E,Partner_Data!$A:$A,"C05",Partner_Data!$C:$C,$A14),0)-$B14)),"n/a"))) -> 84.760597
A16: Sample sizes (delivered shipments with a valid date). Cells below the Inputs minimum are shaded orange.
A17: Route | B17: Current delivered | C17: C01 delivered | D17: C02 delivered | E17: C03 delivered | F17: C04 delivered | G17: C05 delivered
A18: Abu Dhabi | B18: =SUMIFS(Partner_Data!$E:$E,Partner_Data!$A:$A,Inputs!$B$6,Partner_Data!$C:$C,$A18) -> 238 | C18: =SUMIFS(Partner_Data!$E:$E,Partner_Data!$A:$A,"C01",Partner_Data!$C:$C,$A18) -> 625 | D18: =SUMIFS(Partner_Data!$E:$E,Partner_Data!$A:$A,"C02",Partner_Data!$C:$C,$A18) -> 359 | E18: =SUMIFS(Partner_Data!$E:$E,Partner_Data!$A:$A,"C03",Partner_Data!$C:$C,$A18) -> 238 | F18: =SUMIFS(Partner_Data!$E:$E,Partner_Data!$A:$A,"C04",Partner_Data!$C:$C,$A18) -> 494 | G18: =SUMIFS(Partner_Data!$E:$E,Partner_Data!$A:$A,"C05",Partner_Data!$C:$C,$A18) -> 294
A19: Ajman | B19: =SUMIFS(Partner_Data!$E:$E,Partner_Data!$A:$A,Inputs!$B$6,Partner_Data!$C:$C,$A19) -> 169 | C19: =SUMIFS(Partner_Data!$E:$E,Partner_Data!$A:$A,"C01",Partner_Data!$C:$C,$A19) -> 104 | D19: =SUMIFS(Partner_Data!$E:$E,Partner_Data!$A:$A,"C02",Partner_Data!$C:$C,$A19) -> 122 | E19: =SUMIFS(Partner_Data!$E:$E,Partner_Data!$A:$A,"C03",Partner_Data!$C:$C,$A19) -> 169 | F19: =SUMIFS(Partner_Data!$E:$E,Partner_Data!$A:$A,"C04",Partner_Data!$C:$C,$A19) -> 80 | G19: =SUMIFS(Partner_Data!$E:$E,Partner_Data!$A:$A,"C05",Partner_Data!$C:$C,$A19) -> 109
A20: Dubai | B20: =SUMIFS(Partner_Data!$E:$E,Partner_Data!$A:$A,Inputs!$B$6,Partner_Data!$C:$C,$A20) -> 710 | C20: =SUMIFS(Partner_Data!$E:$E,Partner_Data!$A:$A,"C01",Partner_Data!$C:$C,$A20) -> 968 | D20: =SUMIFS(Partner_Data!$E:$E,Partner_Data!$A:$A,"C02",Partner_Data!$C:$C,$A20) -> 769 | E20: =SUMIFS(Partner_Data!$E:$E,Partner_Data!$A:$A,"C03",Partner_Data!$C:$C,$A20) -> 710 | F20: =SUMIFS(Partner_Data!$E:$E,Partner_Data!$A:$A,"C04",Partner_Data!$C:$C,$A20) -> 379 | G20: =SUMIFS(Partner_Data!$E:$E,Partner_Data!$A:$A,"C05",Partner_Data!$C:$C,$A20) -> 466
A21: Fujairah | B21: =SUMIFS(Partner_Data!$E:$E,Partner_Data!$A:$A,Inputs!$B$6,Partner_Data!$C:$C,$A21) -> 89 | C21: =SUMIFS(Partner_Data!$E:$E,Partner_Data!$A:$A,"C01",Partner_Data!$C:$C,$A21) -> 56 | D21: =SUMIFS(Partner_Data!$E:$E,Partner_Data!$A:$A,"C02",Partner_Data!$C:$C,$A21) -> 71 | E21: =SUMIFS(Partner_Data!$E:$E,Partner_Data!$A:$A,"C03",Partner_Data!$C:$C,$A21) -> 89 | F21: =SUMIFS(Partner_Data!$E:$E,Partner_Data!$A:$A,"C04",Partner_Data!$C:$C,$A21) -> 50 | G21: =SUMIFS(Partner_Data!$E:$E,Partner_Data!$A:$A,"C05",Partner_Data!$C:$C,$A21) -> 49
A22: Ras Al Khaimah | B22: =SUMIFS(Partner_Data!$E:$E,Partner_Data!$A:$A,Inputs!$B$6,Partner_Data!$C:$C,$A22) -> 140 | C22: =SUMIFS(Partner_Data!$E:$E,Partner_Data!$A:$A,"C01",Partner_Data!$C:$C,$A22) -> 87 | D22: =SUMIFS(Partner_Data!$E:$E,Partner_Data!$A:$A,"C02",Partner_Data!$C:$C,$A22) -> 123 | E22: =SUMIFS(Partner_Data!$E:$E,Partner_Data!$A:$A,"C03",Partner_Data!$C:$C,$A22) -> 140 | F22: =SUMIFS(Partner_Data!$E:$E,Partner_Data!$A:$A,"C04",Partner_Data!$C:$C,$A22) -> 71 | G22: =SUMIFS(Partner_Data!$E:$E,Partner_Data!$A:$A,"C05",Partner_Data!$C:$C,$A22) -> 79
A23: Sharjah | B23: =SUMIFS(Partner_Data!$E:$E,Partner_Data!$A:$A,Inputs!$B$6,Partner_Data!$C:$C,$A23) -> 449 | C23: =SUMIFS(Partner_Data!$E:$E,Partner_Data!$A:$A,"C01",Partner_Data!$C:$C,$A23) -> 281 | D23: =SUMIFS(Partner_Data!$E:$E,Partner_Data!$A:$A,"C02",Partner_Data!$C:$C,$A23) -> 354 | E23: =SUMIFS(Partner_Data!$E:$E,Partner_Data!$A:$A,"C03",Partner_Data!$C:$C,$A23) -> 449 | F23: =SUMIFS(Partner_Data!$E:$E,Partner_Data!$A:$A,"C04",Partner_Data!$C:$C,$A23) -> 209 | G23: =SUMIFS(Partner_Data!$E:$E,Partner_Data!$A:$A,"C05",Partner_Data!$C:$C,$A23) -> 249
A24: Umm Al Quwain | B24: =SUMIFS(Partner_Data!$E:$E,Partner_Data!$A:$A,Inputs!$B$6,Partner_Data!$C:$C,$A24) -> 72 | C24: =SUMIFS(Partner_Data!$E:$E,Partner_Data!$A:$A,"C01",Partner_Data!$C:$C,$A24) -> 47 | D24: =SUMIFS(Partner_Data!$E:$E,Partner_Data!$A:$A,"C02",Partner_Data!$C:$C,$A24) -> 48 | E24: =SUMIFS(Partner_Data!$E:$E,Partner_Data!$A:$A,"C03",Partner_Data!$C:$C,$A24) -> 72 | F24: =SUMIFS(Partner_Data!$E:$E,Partner_Data!$A:$A,"C04",Partner_Data!$C:$C,$A24) -> 31 | G24: =SUMIFS(Partner_Data!$E:$E,Partner_Data!$A:$A,"C05",Partner_Data!$C:$C,$A24) -> 47
A25: All emirates | B25: =SUMIFS(Partner_Data!$E:$E,Partner_Data!$A:$A,Inputs!$B$6,Partner_Data!$C:$C,$A25) -> 1867 | C25: =SUMIFS(Partner_Data!$E:$E,Partner_Data!$A:$A,"C01",Partner_Data!$C:$C,$A25) -> 2168 | D25: =SUMIFS(Partner_Data!$E:$E,Partner_Data!$A:$A,"C02",Partner_Data!$C:$C,$A25) -> 1846 | E25: =SUMIFS(Partner_Data!$E:$E,Partner_Data!$A:$A,"C03",Partner_Data!$C:$C,$A25) -> 1867 | F25: =SUMIFS(Partner_Data!$E:$E,Partner_Data!$A:$A,"C04",Partner_Data!$C:$C,$A25) -> 1314 | G25: =SUMIFS(Partner_Data!$E:$E,Partner_Data!$A:$A,"C05",Partner_Data!$C:$C,$A25) -> 1293
A27: Green = within the cost threshold on Inputs; red = above it. Check the sample table before recommending a small-sample cell.

Sheet Decision
A1: Business decision (updates with Inputs)
A4: 1. Finding | B4: ="Finding: "&IF(Model!$B$5="All emirates","across all emirates","in "&Model!$B$5)&", "&Model!$B$6&" ("&Inputs!$B$17&")"&" delivered "&TEXT(Model!$B$15,"0.0%")&" of shipments on time, against "&TEXT(Model!$B$22,"0.0%")&" for "&Model!$B$7&" ("&Inputs!$B$18&")"&" and a route average of "&TEXT(Model!$B$30,"0.0%")&" (company average "&TEXT(Model!$B$33,"0.0%")&")." -> Finding: in Ras Al Khaimah, C03 (CityHop Riders) delivered 69.3% of shipments on time, against 87.8% for C02 (DesertLink Express) and a route average of 82.0% (company average 85.4%).
